<?xml version="1.0" ?>
<!-- =================================================================================== -->
<!-- |    This document was autogenerated by xacro from /home/ryu/ws_chickfac/src/serbot/urdf/serving_robot.xacro | -->
<!-- |    EDITING THIS FILE BY HAND IS NOT RECOMMENDED                                 | -->
<!-- =================================================================================== -->
<robot name="serving_robot">
  <!-- Specify some standard inertial calculations https://en.wikipedia.org/wiki/List_of_moments_of_inertia -->
  <!-- These make use of xacro's mathematical functionality -->
  <gazebo>
    <plugin filename="libgazebo_ros_diff_drive.so" name="diff_drive_controller">
      <ros>
        <namespace>robot</namespace>
        <remapping>cmd_vel:=/cmd_vel</remapping>
        <remapping>odom:=/odom</remapping>
      </ros>
      <!-- Wheel Information -->
      <left_joint>left_wheel_joint</left_joint>
      <right_joint>right_wheel_joint</right_joint>
      <wheel_separation>0.35</wheel_separation>
      <wheel_radius>0.05</wheel_radius>
      <wheel_diameter>0.1</wheel_diameter>
      <update_rate>50</update_rate>
      <!-- Limits -->
      <max_wheel_torque>200</max_wheel_torque>
      <max_wheel_acceleration>10.0</max_wheel_acceleration>
      <!-- Output -->
      <odometry_frame>odom</odometry_frame>
      <robot_base_frame>base_link</robot_base_frame>
      <publish_odom>true</publish_odom>
      <publish_odom_tf>true</publish_odom_tf>
      <publish_wheel_tf>true</publish_wheel_tf>
    </plugin>
  </gazebo>
  <gazebo reference="laser_frame">
    <material>Gazebo/White</material>
    <sensor name="laser" type="ray">
      <pose>0 0 0 0 0 0</pose>
      <visualize>true</visualize>
      <update_rate>10</update_rate>
      <ray>
        <scan>
          <horizontal>
            <samples>360</samples>
            <min_angle>-3.14</min_angle>
            <max_angle>3.14</max_angle>
          </horizontal>
        </scan>
        <range>
          <min>0.3</min>
          <max>12</max>
        </range>
      </ray>
      <plugin filename="libgazebo_ros_laser.so" name="laser">
        <ros>
          <namespace>robot</namespace>
          <remapping>scan:=/scan</remapping>
        </ros>
        <frame_name>laser_frame</frame_name>
        <update_rate>30</update_rate>
      </plugin>
    </sensor>
  </gazebo>
  <gazebo reference="imu_link">
    <material>Gazebo/White</material>
    <plugin filename="libgazebo_ros_imu_sensor.so" name="imu">
      <ros>
        <namespace>robot</namespace>
        <remapping>imu:=/imu/data</remapping>
      </ros>
      <frame_name>imu_link</frame_name>
      <update_rate>50</update_rate>
    </plugin>
  </gazebo>
  <!-- COLOR -->
  <material name="white">
    <color rgba="1 1 1 1"/>
  </material>
  <material name="blue">
    <color rgba="0 0 1 1"/>
  </material>
  <material name="black">
    <color rgba="0 0 0 1"/>
  </material>
  <material name="red">
    <color rgba="1 0 0 1"/>
  </material>
  <!-- BASE LINK -->
  <link name="base_link">
    </link>
  <!-- BODY LINK -->
  <joint name="body_joint" type="fixed">
    <parent link="base_link"/>
    <child link="body"/>
    <origin xyz="0 0 0"/>
  </joint>
  <link name="body">
    <visual>
      <origin xyz="0.0 0.0 0.1"/>
      <geometry>
        <cylinder length="0.2" radius="0.2"/>
      </geometry>
      <material name="white"/>
    </visual>
    <collision>
      <origin xyz="0.0 0.0 0.1"/>
      <geometry>
        <cylinder length="0.2" radius="0.2"/>
      </geometry>
    </collision>
    <inertial>
      <origin rpy="0 0 0" xyz="0.0 0.0 0.1"/>
      <mass value="5.0"/>
      <inertia ixx="0.06666666666666668" ixy="0.0" ixz="0.0" iyy="0.06666666666666668" iyz="0.0" izz="0.10000000000000002"/>
    </inertial>
  </link>
  <gazebo reference="body">
    <material>Gazebo/White</material>
  </gazebo>
  <!-- LEFT WHEEL LINK -->
  <joint name="left_wheel_joint" type="continuous">
    <parent link="base_link"/>
    <child link="left_wheel"/>
    <origin rpy="-1.5707963267948966 0 0" xyz="0.04 0.2 0"/>
    <axis xyz="0 0 1"/>
  </joint>
  <link name="left_wheel">
    <visual>
      <geometry>
        <cylinder length="0.03" radius="0.05"/>
      </geometry>
      <material name="blue"/>
    </visual>
    <collision>
      <geometry>
        <cylinder length="0.03" radius="0.05"/>
      </geometry>
    </collision>
    <inertial>
      <origin rpy="0 0 0" xyz="0 0 0"/>
      <mass value="0.2"/>
      <inertia ixx="0.00014000000000000001" ixy="0.0" ixz="0.0" iyy="0.00014000000000000001" iyz="0.0" izz="0.00025000000000000006"/>
    </inertial>
  </link>
  <gazebo reference="left_wheel">
    <material>Gazebo/Black</material>
  </gazebo>
  <!-- RIGHT WHEEL LINK -->
  <joint name="right_wheel_joint" type="continuous">
    <parent link="base_link"/>
    <child link="right_wheel"/>
    <origin rpy="1.5707963267948966 0 0" xyz="0.04 -0.2 0"/>
    <axis xyz="0 0 -1"/>
  </joint>
  <link name="right_wheel">
    <visual>
      <geometry>
        <cylinder length="0.03" radius="0.05"/>
      </geometry>
      <material name="white"/>
    </visual>
    <collision>
      <geometry>
        <cylinder length="0.03" radius="0.05"/>
      </geometry>
    </collision>
    <inertial>
      <origin rpy="0 0 0" xyz="0 0 0"/>
      <mass value="0.2"/>
      <inertia ixx="0.00014000000000000001" ixy="0.0" ixz="0.0" iyy="0.00014000000000000001" iyz="0.0" izz="0.00025000000000000006"/>
    </inertial>
  </link>
  <gazebo reference="right_wheel">
    <material>Gazebo/Black</material>
  </gazebo>
  <!-- CASTER WHEEL LINK -->
  <joint name="caster_wheel_joint" type="fixed">
    <parent link="body"/>
    <child link="caster_wheel"/>
    <origin xyz="-0.12 0 0"/>
  </joint>
  <link name="caster_wheel">
    <visual>
      <geometry>
        <sphere radius="0.05"/>
      </geometry>
      <material name="white"/>
    </visual>
    <collision>
      <geometry>
        <sphere radius="0.05"/>
      </geometry>
    </collision>
    <inertial>
      <origin rpy="0 0 0" xyz="0 0 0"/>
      <mass value="0.2"/>
      <inertia ixx="0.0002000000000000001" ixy="0.0" ixz="0.0" iyy="0.0002000000000000001" iyz="0.0" izz="0.0002000000000000001"/>
    </inertial>
  </link>
  <gazebo reference="caster_wheel">
    <material>Gazebo/Blue</material>
    <mu1 value="0.001"/>
    <mu2 value="0.001"/>
  </gazebo>
  <!-- LEFT PANEL LINK -->
  <joint name="left_panel_joint" type="fixed">
    <parent link="body"/>
    <child link="left_panel"/>
    <origin xyz="0 0.2 0.1"/>
  </joint>
  <link name="left_panel">
    <visual>
      <origin xyz="0.0 0.0 0.3"/>
      <geometry>
        <box size="0.05 0.01 0.6"/>
      </geometry>
      <material name="white"/>
    </visual>
    <collision>
      <origin xyz="0.0 0.0 0.3"/>
      <geometry>
        <box size="0.05 0.01 0.6"/>
      </geometry>
    </collision>
    <inertial>
      <origin rpy="0 0 0" xyz="0.0 0.0 0.3"/>
      <mass value="0.1"/>
      <inertia ixx="0.0030008333333333332" ixy="0.0" ixz="0.0" iyy="0.0030208333333333333" iyz="0.0" izz="2.166666666666667e-05"/>
    </inertial>
  </link>
  <gazebo reference="left_panel">
    <material>Gazebo/White</material>
  </gazebo>
  <!-- RIGHT PANEL LINK -->
  <joint name="right_panel_joint" type="fixed">
    <parent link="body"/>
    <child link="right_panel"/>
    <origin xyz="0 -0.2 0.1"/>
  </joint>
  <link name="right_panel">
    <visual>
      <origin xyz="0.0 0.0 0.3"/>
      <geometry>
        <box size="0.05 0.01 0.6"/>
      </geometry>
      <material name="white"/>
    </visual>
    <collision>
      <origin xyz="0.0 0.0 0.3"/>
      <geometry>
        <box size="0.05 0.01 0.6"/>
      </geometry>
    </collision>
    <inertial>
      <origin rpy="0 0 0" xyz="0.0 0.0 0.3"/>
      <mass value="0.1"/>
      <inertia ixx="0.0030008333333333332" ixy="0.0" ixz="0.0" iyy="0.0030208333333333333" iyz="0.0" izz="2.166666666666667e-05"/>
    </inertial>
  </link>
  <gazebo reference="right_panel">
    <material>Gazebo/White</material>
  </gazebo>
  <!-- TOP PANEL LINK -->
  <joint name="top_panel_joint" type="fixed">
    <parent link="right_panel"/>
    <child link="top_panel"/>
    <origin xyz="0 0.2 0.59"/>
  </joint>
  <link name="top_panel">
    <visual>
      <origin xyz="0.0 0.0 0.005"/>
      <geometry>
        <box size="0.05 0.4 0.01"/>
      </geometry>
      <material name="white"/>
    </visual>
    <collision>
      <origin xyz="0.0 0.0 0.005"/>
      <geometry>
        <box size="0.05 0.4 0.01"/>
      </geometry>
    </collision>
    <inertial>
      <origin rpy="0 0 0" xyz="0.0 0.0 0.005"/>
      <mass value="0.1"/>
      <inertia ixx="0.0013341666666666669" ixy="0.0" ixz="0.0" iyy="2.166666666666667e-05" iyz="0.0" izz="0.001354166666666667"/>
    </inertial>
  </link>
  <gazebo reference="top_panel">
    <material>Gazebo/White</material>
  </gazebo>
  <!-- TRAY1 LINK -->
  <joint name="tray1_joint" type="fixed">
    <parent link="right_panel"/>
    <child link="tray1"/>
    <origin xyz="0 0.2 0.2"/>
  </joint>
  <link name="tray1">
    <visual>
      <origin xyz="0.0 0.0 0.001"/>
      <geometry>
        <cylinder length="0.002" radius="0.2"/>
      </geometry>
      <material name="white"/>
    </visual>
    <collision>
      <origin xyz="0.0 0.0 0.001"/>
      <geometry>
        <cylinder length="0.002" radius="0.2"/>
      </geometry>
    </collision>
    <inertial>
      <origin rpy="0 0 0" xyz="0.0 0.0 0.001"/>
      <mass value="0.005"/>
      <inertia ixx="5.000166666666667e-05" ixy="0.0" ixz="0.0" iyy="5.000166666666667e-05" iyz="0.0" izz="0.00010000000000000002"/>
    </inertial>
  </link>
  <gazebo reference="tray1">
    <material>Gazebo/Black</material>
  </gazebo>
  <!-- TRAY2 LINK -->
  <joint name="tray2_joint" type="fixed">
    <parent link="right_panel"/>
    <child link="tray2"/>
    <origin xyz="0 0.2 0.4"/>
  </joint>
  <link name="tray2">
    <visual>
      <origin xyz="0.0 0.0 0.001"/>
      <geometry>
        <cylinder length="0.002" radius="0.2"/>
      </geometry>
      <material name="white"/>
    </visual>
    <collision>
      <origin xyz="0.0 0.0 0.001"/>
      <geometry>
        <cylinder length="0.002" radius="0.2"/>
      </geometry>
    </collision>
    <inertial>
      <origin rpy="0 0 0" xyz="0.0 0.0 0.001"/>
      <mass value="0.005"/>
      <inertia ixx="5.000166666666667e-05" ixy="0.0" ixz="0.0" iyy="5.000166666666667e-05" iyz="0.0" izz="0.00010000000000000002"/>
    </inertial>
  </link>
  <gazebo reference="tray2">
    <material>Gazebo/Black</material>
  </gazebo>
  <!-- LiDAR -->
  <joint name="laser_joint" type="fixed">
    <parent link="body"/>
    <child link="laser_frame"/>
    <origin rpy="0 0 0" xyz="0 0 0.71"/>
  </joint>
  <link name="laser_frame">
    <visual>
      <geometry>
        <cylinder length="0.03" radius="0.03"/>
      </geometry>
      <material name="white"/>
    </visual>
    <collision>
      <geometry>
        <cylinder length="0.03" radius="0.03"/>
      </geometry>
    </collision>
  </link>
  <!-- Imu -->
  <joint name="imu_joint" type="fixed">
    <parent link="base_link"/>
    <child link="imu_link"/>
    <origin rpy="0 0 0" xyz="0 0 0.68"/>
  </joint>
  <link name="imu_link"/>
</robot>
